Workbook
Name Slicer_Region: #N/A

Sheet Raw_Data
A1: Order_ID | B1: Order_Date | C1: Region | D1: City | E1: Sales_Channel | F1: Customer_Type | G1: Product | H1: Category | I1: Quantity | J1: Unit_Price_INR | K1: Discount | L1: Payment_Method | M1: Salesperson | N1: Order_Status | O1: Gross_Sales_INR | P1: Discount_Amount_INR | Q1: Net_Sales_INR | R1: Delivery_Days
A2: ORD-10585 | B2: 45839 | C2: North | D2: Lucknow | E2: Retail Store | F2: Individual | G2: Smartphone | H2: Electronics | I2: 5 | J2: 26500 | K2: 0 | L2: Cash on Delivery | M2: Rohan Sharma | N2: Delivered | O2: 132500 | P2: 0 | Q2: 132500 | R2: 3
A3: ORD-10397 | B3: 45839 | C3: West | D3: Surat | E3: Retail Store | F3: Small Business | G3: Backpack | H3: Accessories | I3: 1 | J3: 2500 | K3: 0.03 | L3: Net Banking | M3: Aarav Mehta | N3: Delivered | O3: 2500 | P3: 75 | Q3: 2425 | R3: 2
A4: ORD-10292 | B4: 45839 | C4: West | D4: Surat | E4: Retail Store | F4: Small Business | G4: Laptop | H4: Electronics | I4: 3 | J4: 57740 | K4: 0.05 | L4: Net Banking | M4: Priya Nair | N4: Delivered | O4: 173220 | P4: 8661 | Q4: 164559 | R4: 1
A5: ORD-10085 | B5: 45840 | C5: South | D5: Chennai | E5: Online | F5: Individual | G5: Mouse | H5: Accessories | I5: 3 | J5: 990 | K5: 0 | L5: Net Banking | M5: Vikram Singh | N5: Cancelled | O5: 0 | P5: 0 | Q5: 0
A6: ORD-10198 | B6: 45840 | C6: South | D6: Hyderabad | E6: Retail Store | F6: Individual | G6: Printer | H6: Office Equipment | I6: 2 | J6: 13300 | K6: 0.15 | L6: Cash on Delivery | M6: Sneha Iyer | N6: Delivered | O6: 26600 | P6: 3990 | Q6: 22610 | R6: 3
A7: ORD-10526 | B7: 45840 | C7: North | D7: Noida | E7: Retail Store | F7: Enterprise | G7: Smartphone | H7: Electronics | I7: 1 | J7: 29800 | K7: 0.1 | L7: Debit Card | M7: Karan Patel | N7: Delivered | O7: 29800 | P7: 2980 | Q7: 26820 | R7: 3
A8: ORD-10121 | B8: 45840 | C8: North | D8: Delhi | E8: Retail Store | F8: Small Business | G8: External SSD | H8: Storage | I8: 1 | J8: 6710 | K8: 0 | L8: Net Banking | M8: Vikram Singh | N8: Delivered | O8: 6710 | P8: 0 | Q8: 6710 | R8: 2
A9: ORD-10109 | B9: 45842 | C9: West | D9: Mumbai | E9: Online | F9: Small Business | G9: Keyboard | H9: Accessories | I9: 3 | J9: 1790 | K9: 0.05 | L9: Net Banking | M9: Sneha Iyer | N9: Delivered | O9: 5370 | P9: 268.5 | Q9: 5101.5 | R9: 3
A10: ORD-10527 | B10: 45842 | C10: West | D10: Mumbai | E10: Online | F10: Small Business | G10: External SSD | H10: Storage | I10: 2 | J10: 6850 | K10: 0.05 | L10: UPI | M10: Rohan Sharma | N10: Delivered | O10: 13700 | P10: 685 | Q10: 13015 | R10: 3
A11: ORD-10083 | B11: 45842 | C11: North | D11: Delhi | E11: Retail Store | F11: Enterprise | G11: External SSD | H11: Storage | I11: 4 | J11: 6700 | K11: 0.03 | L11: UPI | M11: Ananya Rao | N11: Delivered | O11: 26800 | P11: 804 | Q11: 25996 | R11: 4
A12: ORD-10320 | B12: 45842 | C12: West | D12: Surat | E12: Online | F12: Individual | G12: Keyboard | H12: Accessories | I12: 1 | J12: 1740 | K12: 0 | L12: Credit Card | M12: Priya Nair | N12: Delivered | O12: 1740 | P12: 0 | Q12: 1740 | R12: 4
A13: ORD-10530 | B13: 45843 | C13: West | D13: Mumbai | E13: Corporate | F13: Individual | G13: Mouse | H13: Accessories | I13: 5 | J13: 950 | K13: 0.1 | L13: UPI | M13: Neha Kapoor | N13: Delivered | O13: 4750 | P13: 475 | Q13: 4275 | R13: 3
A14: ORD-10565 | B14: 45843 | C14: South | D14: Hyderabad | E14: Online | F14: Individual | G14: Office Chair | H14: Furniture | I14: 2 | J14: 11810 | K14: 0.08 | L14: Credit Card | M14: Neha Kapoor | N14: Delivered | O14: 23620 | P14: 1889.6 | Q14: 21730.4 | R14: 2
A15: ORD-10375 | B15: 45844 | C15: South | D15: Chennai | E15: Retail Store | F15: Individual | G15: Laptop | H15: Electronics | I15: 3 | J15: 64490 | K15: 0 | L15: Net Banking | M15: Aarav Mehta | N15: Delivered | O15: 193470 | P15: 0 | Q15: 193470 | R15: 1
A16: ORD-10381 | B16: 45844 | C16: West | D16: Surat | E16: Online | F16: Individual | G16: Laptop | H16: Electronics | I16: 1 | J16: 64500 | K16: 0.08 | L16: Net Banking | M16: Priya Nair | N16: Delivered | O16: 64500 | P16: 5160 | Q16: 59340 | R16: 5
A17: ORD-10330 | B17: 45844 | C17: West | D17: Pune | E17: Retail Store | F17: Individual | G17: External SSD | H17: Storage | I17: 4 | J17: 7640 | K17: 0.05 | L17: Credit Card | M17: Priya Nair | N17: Delivered | O17: 30560 | P17: 1528 | Q17: 29032 | R17: 2
... A43: ORD-10327 | B43: 45861 | C43: North | D43: Delhi | E43: Corporate | F43: Individual | G43: Keyboard | H43: Accessories | I43: 1 | J43: 1740 | K43: 0.08 | L43: Net Banking | M43: Sneha Iyer | N43: Delivered | O43: 1740 | P43: 139.2 | Q43: 1600.8 | R43: 3
A44: ORD-10144 | B44: 45861 | C44: South | D44: Kochi | E44: Corporate | F44: Individual | G44: Wireless Headphones | H44: Electronics | I44: 1 | J44: 3170 | K44: 0 | L44: UPI | M44: Priya Nair | N44: Cancelled | O44: 0 | P44: 0 | Q44: 0
A45: ORD-10385 | B45: 45861 | C45: West | D45: Pune | E45: Retail Store | F45: Individual | G45: Mouse | H45: Accessories | I45: 2 | J45: 880 | K45: 0.08 | L45: Credit Card | M45: Rohan Sharma | N45: Delivered | O45: 1760 | P45: 140.8 | Q45: 1619.2 | R45: 1
A46: ORD-10631 | B46: 45861 | C46: South | D46: Hyderabad | E46: Corporate | F46: Enterprise | G46: Monitor | H46: Electronics | I46: 1 | J46: 17400 | K46: 0.05 | L46: UPI | M46: Karan Patel | N46: Delivered | O46: 17400 | P46: 870 | Q46: 16530 | R46: 3
A47: ORD-10432 | B47: 45863 | C47: West | D47: Mumbai | E47: Online | F47: Individual | G47: Wireless Headphones | H47: Electronics | I47: 1 | J47: 3030 | K47: 0.03 | L47: Net Banking | M47: Aarav Mehta | N47: Delivered | O47: 3030 | P47: 90.9 | Q47: 2939.1 | R47: 5
A48: ORD-10536 | B48: 45863 | C48: South | D48: Kochi | E48: Corporate | F48: Small Business | G48: Wireless Headphones | H48: Electronics | I48: 2 | J48: 3140 | K48: 0.1 | L48: Debit Card | M48: Karan Patel | N48: Delivered | O48: 6280 | P48: 628 | Q48: 5652 | R48: 2
A49: ORD-10328 | B49: 45863 | C49: West | D49: Ahmedabad | E49: Corporate | F49: Individual | G49: Laptop | H49: Electronics | I49: 2 | J49: 60000 | K49: 0.03 | L49: UPI | M49: Sneha Iyer | N49: Delivered | O49: 120000 | P49: 3600 | Q49: 116400 | R49: 2
A50: ORD-10476 | B50: 45863 | C50: East | D50: Bhubaneswar | E50: Retail Store | F50: Enterprise | G50: Laptop | H50: Electronics | I50: 1 | J50: 59470 | K50: 0.08 | L50: Debit Card | M50: Karan Patel | N50: Delivered | O50: 59470 | P50: 4757.6 | Q50: 54712.4 | R50: 1
A51: ORD-10590 | B51: 45865 | C51: North | D51: Delhi | E51: Online | F51: Small Business | G51: Laptop | H51: Electronics | I51: 1 | J51: 65160 | K51: 0 | L51: Credit Card | M51: Ananya Rao | N51: Delivered | O51: 65160 | P51: 0 | Q51: 65160 | R51: 2
A52: ORD-10143 | B52: 45865 | C52: South | D52: Chennai | E52: Online | F52: Small Business | G52: Printer | H52: Office Equipment | I52: 1 | J52: 13060 | K52: 0.08 | L52: UPI | M52: Vikram Singh | N52: Delivered | O52: 13060 | P52: 1044.8 | Q52: 12015.2 | R52: 4
A53: ORD-10141 | B53: 45865 | C53: North | D53: Lucknow | E53: Online | F53: Individual | G53: Power Bank | H53: Accessories | I53: 2 | J53: 1680 | K53: 0.03 | L53: UPI | M53: Priya Nair | N53: Delivered | O53: 3360 | P53: 100.8 | Q53: 3259.2 | R53: 4
A54: ORD-10305 | B54: 45866 | C54: South | D54: Bengaluru | E54: Retail Store | F54: Individual | G54: Laptop | H54: Electronics | I54: 3 | J54: 65510 | K54: 0.08 | L54: Credit Card | M54: Neha Kapoor | N54: Delivered | O54: 196530 | P54: 15722.4 | Q54: 180807.6 | R54: 3
A55: ORD-10507 | B55: 45866 | C55: West | D55: Surat | E55: Online | F55: Small Business | G55: Wireless Headphones | H55: Electronics | I55: 5 | J55: 3320 | K55: 0.05 | L55: UPI | M55: Priya Nair | N55: Delivered | O55: 16600 | P55: 830 | Q55: 15770 | R55: 3
A56: ORD-10388 | B56: 45866 | C56: North | D56: Delhi | E56: Retail Store | F56: Enterprise | G56: Wireless Headphones | H56: Electronics | I56: 1 | J56: 3310 | K56: 0.05 | L56: Debit Card | M56: Neha Kapoor | N56: Delivered | O56: 3310 | P56: 165.5 | Q56: 3144.5 | R56: 4
... A74: ORD-10110 | B74: 45875 | C74: West | D74: Surat | E74: Online | F74: Individual | G74: Monitor | H74: Electronics | I74: 1 | J74: 15970 | K74: 0 | L74: Credit Card | M74: Priya Nair | N74: Delivered | O74: 15970 | P74: 0 | Q74: 15970 | R74: 6
A75: ORD-10332 | B75: 45875 | C75: North | E75: Corporate | F75: Small Business | G75: Webcam | H75: Accessories | I75: 1 | J75: 3670 | K75: 0 | L75: Debit Card | M75: Aarav Mehta | N75: Delivered | O75: 3670 | P75: 0 | Q75: 3670 | R75: 2
A76: ORD-10171 | B76: 45877 | C76: South | D76: Bengaluru | E76: Corporate | F76: Small Business | G76: Webcam | H76: Accessories | I76: 3 | J76: 3770 | K76: 0.03 | L76: UPI | M76: Karan Patel | N76: Delivered | O76: 11310 | P76: 339.3 | Q76: 10970.7 | R76: 2
A77: ORD-10030 | B77: 45877 | C77: North | D77: Delhi | E77: Corporate | F77: Individual | G77: Office Desk | H77: Furniture | I77: 5 | J77: 14360 | K77: 0.1 | L77: Debit Card | M77: Rohan Sharma | N77: Delivered | O77: 71800 | P77: 7180 | Q77: 64620 | R77: 5
A78: ORD-10264 | B78: 45877 | C78: North | D78: Lucknow | E78: Retail Store | F78: Individual | G78: Wireless Headphones | H78: Electronics | I78: 4 | J78: 3120 | K78: 0.05 | L78: Debit Card | M78: Neha Kapoor | N78: Delivered | O78: 12480 | P78: 624 | Q78: 11856 | R78: 3
A79: ORD-10020 | B79: 45879 | C79: East | D79: Bhubaneswar | E79: Online | F79: Individual | G79: Mouse | H79: Accessories | I79: 3 | J79: 960 | K79: 0.15 | L79: Cash on Delivery | M79: Sneha Iyer | N79: Delivered | O79: 2880 | P79: 432 | Q79: 2448 | R79: 6
A80: ORD-10352 | B80: 45879 | C80: South | D80: Bengaluru | E80: Online | F80: Individual | G80: Mouse | H80: Accessories | I80: 2 | J80: 920 | K80: 0.08 | L80: UPI | M80: Priya Nair | N80: Delivered | O80: 1840 | P80: 147.2 | Q80: 1692.8 | R80: 5
A81: ORD-10055 | B81: 45879 | C81: South | D81: Kochi | E81: Retail Store | F81: Individual | G81: Power Bank | H81: Accessories | I81: 1 | J81: 1900 | K81: 0.1 | L81: Net Banking | M81: Aarav Mehta | N81: Delivered | O81: 1900 | P81: 190 | Q81: 1710 | R81: 4
A82: ORD-10147 | B82: 45880 | C82: West | D82: Pune | E82: Online | F82: Individual | G82: Keyboard | H82: Accessories | I82: 1 | J82: 1900 | K82: 0.05 | L82: UPI | M82: Aarav Mehta | N82: Delivered | O82: 1900 | P82: 95 | Q82: 1805 | R82: 4
...

Sheet Cleaned_data
A1: Order ID | B1: Order Date | C1: Region | D1: City | E1: Sales Channel | F1: Customer Type | G1: Product | H1: Category | I1: Quantity | J1: Unit Price INR | K1: Discount | L1: Payment Method | M1: Salesperson | N1: Order Status | O1: Gross Sales INR | P1: Discount Amount INR | Q1: Net Sales INR | R1: Delivery Days | S1: Sales Month
A2: ORD-10585 | B2: 45839 | C2: North | D2: Lucknow | E2: Retail Store | F2: Individual | G2: Smartphone | H2: Electronics | I2: 5 | J2: 26500 | K2: 0 | L2: Cash on Delivery | M2: Rohan Sharma | N2: Delivered | O2: 132500 | P2: 0 | Q2: 132500 | R2: 3 | S2: =DATE(YEAR(B2),MONTH(B2),1) -> 45839
A3: ORD-10397 | B3: 45839 | C3: West | D3: Surat | E3: Retail Store | F3: Small Business | G3: Backpack | H3: Accessories | I3: 1 | J3: 2500 | K3: 0.03 | L3: Net Banking | M3: Aarav Mehta | N3: Delivered | O3: 2500 | P3: 75 | Q3: 2425 | R3: 2 | S3: =DATE(YEAR(B3),MONTH(B3),1) -> 45839
A4: ORD-10292 | B4: 45839 | C4: West | D4: Surat | E4: Retail Store | F4: Small Business | G4: Laptop | H4: Electronics | I4: 3 | J4: 57740 | K4: 0.05 | L4: Net Banking | M4: Priya Nair | N4: Delivered | O4: 173220 | P4: 8661 | Q4: 164559 | R4: 1 | S4: =DATE(YEAR(B4),MONTH(B4),1) -> 45839
A5: ORD-10085 | B5: 45840 | C5: South | D5: Chennai | E5: Online | F5: Individual | G5: Mouse | H5: Accessories | I5: 3 | J5: 990 | K5: 0 | L5: Net Banking | M5: Vikram Singh | N5: Cancelled | O5: 0 | P5: 0 | Q5: 0 | S5: =DATE(YEAR(B5),MONTH(B5),1) -> 45839
A6: ORD-10198 | B6: 45840 | C6: South | D6: Hyderabad | E6: Retail Store | F6: Individual | G6: Printer | H6: Office Equipment | I6: 2 | J6: 13300 | K6: 0.15 | L6: Cash on Delivery | M6: Sneha Iyer | N6: Delivered | O6: 26600 | P6: 3990 | Q6: 22610 | R6: 3 | S6: =DATE(YEAR(B6),MONTH(B6),1) -> 45839
A7: ORD-10526 | B7: 45840 | C7: North | D7: Noida | E7: Retail Store | F7: Enterprise | G7: Smartphone | H7: Electronics | I7: 1 | J7: 29800 | K7: 0.1 | L7: Debit Card | M7: Karan Patel | N7: Delivered | O7: 29800 | P7: 2980 | Q7: 26820 | R7: 3 | S7: =DATE(YEAR(B7),MONTH(B7),1) -> 45839
A8: ORD-10121 | B8: 45840 | C8: North | D8: Delhi | E8: Retail Store | F8: Small Business | G8: External SSD | H8: Storage | I8: 1 | J8: 6710 | K8: 0 | L8: Net Banking | M8: Vikram Singh | N8: Delivered | O8: 6710 | P8: 0 | Q8: 6710 | R8: 2 | S8: =DATE(YEAR(B8),MONTH(B8),1) -> 45839
A9: ORD-10109 | B9: 45842 | C9: West | D9: Mumbai | E9: Online | F9: Small Business | G9: Keyboard | H9: Accessories | I9: 3 | J9: 1790 | K9: 0.05 | L9: Net Banking | M9: Sneha Iyer | N9: Delivered | O9: 5370 | P9: 268.5 | Q9: 5101.5 | R9: 3 | S9: =DATE(YEAR(B9),MONTH(B9),1) -> 45839
A10: ORD-10527 | B10: 45842 | C10: West | D10: Mumbai | E10: Online | F10: Small Business | G10: External SSD | H10: Storage | I10: 2 | J10: 6850 | K10: 0.05 | L10: UPI | M10: Rohan Sharma | N10: Delivered | O10: 13700 | P10: 685 | Q10: 13015 | R10: 3 | S10: =DATE(YEAR(B10),MONTH(B10),1) -> 45839
A11: ORD-10083 | B11: 45842 | C11: North | D11: Delhi | E11: Retail Store | F11: Enterprise | G11: External SSD | H11: Storage | I11: 4 | J11: 6700 | K11: 0.03 | L11: UPI | M11: Ananya Rao | N11: Delivered | O11: 26800 | P11: 804 | Q11: 25996 | R11: 4 | S11: =DATE(YEAR(B11),MONTH(B11),1) -> 45839
A12: ORD-10320 | B12: 45842 | C12: West | D12: Surat | E12: Online | F12: Individual | G12: Keyboard | H12: Accessories | I12: 1 | J12: 1740 | K12: 0 | L12: Credit Card | M12: Priya Nair | N12: Delivered | O12: 1740 | P12: 0 | Q12: 1740 | R12: 4 | S12: =DATE(YEAR(B12),MONTH(B12),1) -> 45839
A13: ORD-10530 | B13: 45843 | C13: West | D13: Mumbai | E13: Corporate | F13: Individual | G13: Mouse | H13: Accessories | I13: 5 | J13: 950 | K13: 0.1 | L13: UPI | M13: Neha Kapoor | N13: Delivered | O13: 4750 | P13: 475 | Q13: 4275 | R13: 3 | S13: =DATE(YEAR(B13),MONTH(B13),1) -> 45839
A14: ORD-10565 | B14: 45843 | C14: South | D14: Hyderabad | E14: Online | F14: Individual | G14: Office Chair | H14: Furniture | I14: 2 | J14: 11810 | K14: 0.08 | L14: Credit Card | M14: Neha Kapoor | N14: Delivered | O14: 23620 | P14: 1889.6 | Q14: 21730.4 | R14: 2 | S14: =DATE(YEAR(B14),MONTH(B14),1) -> 45839
A15: ORD-10375 | B15: 45844 | C15: South | D15: Chennai | E15: Retail Store | F15: Individual | G15: Laptop | H15: Electronics | I15: 3 | J15: 64490 | K15: 0 | L15: Net Banking | M15: Aarav Mehta | N15: Delivered | O15: 193470 | P15: 0 | Q15: 193470 | R15: 1 | S15: =DATE(YEAR(B15),MONTH(B15),1) -> 45839
A16: ORD-10381 | B16: 45844 | C16: West | D16: Surat | E16: Online | F16: Individual | G16: Laptop | H16: Electronics | I16: 1 | J16: 64500 | K16: 0.08 | L16: Net Banking | M16: Priya Nair | N16: Delivered | O16: 64500 | P16: 5160 | Q16: 59340 | R16: 5 | S16: =DATE(YEAR(B16),MONTH(B16),1) -> 45839
A17: ORD-10330 | B17: 45844 | C17: West | D17: Pune | E17: Retail Store | F17: Individual | G17: External SSD | H17: Storage | I17: 4 | J17: 7640 | K17: 0.05 | L17: Credit Card | M17: Priya Nair | N17: Delivered | O17: 30560 | P17: 1528 | Q17: 29032 | R17: 2 | S17: =DATE(YEAR(B17),MONTH(B17),1) -> 45839
... A43: ORD-10327 | B43: 45861 | C43: North | D43: Delhi | E43: Corporate | F43: Individual | G43: Keyboard | H43: Accessories | I43: 1 | J43: 1740 | K43: 0.08 | L43: Net Banking | M43: Sneha Iyer | N43: Delivered | O43: 1740 | P43: 139.2 | Q43: 1600.8 | R43: 3 | S43: =DATE(YEAR(B43),MONTH(B43),1) -> 45839
A44: ORD-10144 | B44: 45861 | C44: South | D44: Kochi | E44: Corporate | F44: Individual | G44: Wireless Headphones | H44: Electronics | I44: 1 | J44: 3170 | K44: 0 | L44: UPI | M44: Priya Nair | N44: Cancelled | O44: 0 | P44: 0 | Q44: 0 | S44: =DATE(YEAR(B44),MONTH(B44),1) -> 45839
A45: ORD-10385 | B45: 45861 | C45: West | D45: Pune | E45: Retail Store | F45: Individual | G45: Mouse | H45: Accessories | I45: 2 | J45: 880 | K45: 0.08 | L45: Credit Card | M45: Rohan Sharma | N45: Delivered | O45: 1760 | P45: 140.8 | Q45: 1619.2 | R45: 1 | S45: =DATE(YEAR(B45),MONTH(B45),1) -> 45839
A46: ORD-10631 | B46: 45861 | C46: South | D46: Hyderabad | E46: Corporate | F46: Enterprise | G46: Monitor | H46: Electronics | I46: 1 | J46: 17400 | K46: 0.05 | L46: UPI | M46: Karan Patel | N46: Delivered | O46: 17400 | P46: 870 | Q46: 16530 | R46: 3 | S46: =DATE(YEAR(B46),MONTH(B46),1) -> 45839
A47: ORD-10432 | B47: 45863 | C47: West | D47: Mumbai | E47: Online | F47: Individual | G47: Wireless Headphones | H47: Electronics | I47: 1 | J47: 3030 | K47: 0.03 | L47: Net Banking | M47: Aarav Mehta | N47: Delivered | O47: 3030 | P47: 90.9 | Q47: 2939.1 | R47: 5 | S47: =DATE(YEAR(B47),MONTH(B47),1) -> 45839
A48: ORD-10536 | B48: 45863 | C48: South | D48: Kochi | E48: Corporate | F48: Small Business | G48: Wireless Headphones | H48: Electronics | I48: 2 | J48: 3140 | K48: 0.1 | L48: Debit Card | M48: Karan Patel | N48: Delivered | O48: 6280 | P48: 628 | Q48: 5652 | R48: 2 | S48: =DATE(YEAR(B48),MONTH(B48),1) -> 45839
A49: ORD-10328 | B49: 45863 | C49: West | D49: Ahmedabad | E49: Corporate | F49: Individual | G49: Laptop | H49: Electronics | I49: 2 | J49: 60000 | K49: 0.03 | L49: UPI | M49: Sneha Iyer | N49: Delivered | O49: 120000 | P49: 3600 | Q49: 116400 | R49: 2 | S49: =DATE(YEAR(B49),MONTH(B49),1) -> 45839
A50: ORD-10476 | B50: 45863 | C50: East | D50: Bhubaneswar | E50: Retail Store | F50: Enterprise | G50: Laptop | H50: Electronics | I50: 1 | J50: 59470 | K50: 0.08 | L50: Debit Card | M50: Karan Patel | N50: Delivered | O50: 59470 | P50: 4757.6 | Q50: 54712.4 | R50: 1 | S50: =DATE(YEAR(B50),MONTH(B50),1) -> 45839
A51: ORD-10590 | B51: 45865 | C51: North | D51: Delhi | E51: Online | F51: Small Business | G51: Laptop | H51: Electronics | I51: 1 | J51: 65160 | K51: 0 | L51: Credit Card | M51: Ananya Rao | N51: Delivered | O51: 65160 | P51: 0 | Q51: 65160 | R51: 2 | S51: =DATE(YEAR(B51),MONTH(B51),1) -> 45839
A52: ORD-10143 | B52: 45865 | C52: South | D52: Chennai | E52: Online | F52: Small Business | G52: Printer | H52: Office Equipment | I52: 1 | J52: 13060 | K52: 0.08 | L52: UPI | M52: Vikram Singh | N52: Delivered | O52: 13060 | P52: 1044.8 | Q52: 12015.2 | R52: 4 | S52: =DATE(YEAR(B52),MONTH(B52),1) -> 45839
A53: ORD-10141 | B53: 45865 | C53: North | D53: Lucknow | E53: Online | F53: Individual | G53: Power Bank | H53: Accessories | I53: 2 | J53: 1680 | K53: 0.03 | L53: UPI | M53: Priya Nair | N53: Delivered | O53: 3360 | P53: 100.8 | Q53: 3259.2 | R53: 4 | S53: =DATE(YEAR(B53),MONTH(B53),1) -> 45839
A54: ORD-10305 | B54: 45866 | C54: South | D54: Bengaluru | E54: Retail Store | F54: Individual | G54: Laptop | H54: Electronics | I54: 3 | J54: 65510 | K54: 0.08 | L54: Credit Card | M54: Neha Kapoor | N54: Delivered | O54: 196530 | P54: 15722.4 | Q54: 180807.6 | R54: 3 | S54: =DATE(YEAR(B54),MONTH(B54),1) -> 45839
A55: ORD-10507 | B55: 45866 | C55: West | D55: Surat | E55: Online | F55: Small Business | G55: Wireless Headphones | H55: Electronics | I55: 5 | J55: 3320 | K55: 0.05 | L55: UPI | M55: Priya Nair | N55: Delivered | O55: 16600 | P55: 830 | Q55: 15770 | R55: 3 | S55: =DATE(YEAR(B55),MONTH(B55),1) -> 45839
A56: ORD-10388 | B56: 45866 | C56: North | D56: Delhi | E56: Retail Store | F56: Enterprise | G56: Wireless Headphones | H56: Electronics | I56: 1 | J56: 3310 | K56: 0.05 | L56: Debit Card | M56: Neha Kapoor | N56: Delivered | O56: 3310 | P56: 165.5 | Q56: 3144.5 | R56: 4 | S56: =DATE(YEAR(B56),MONTH(B56),1) -> 45839
... A120: ORD-10436 | B120: 45898 | C120: North | D120: Jaipur | E120: Retail Store | F120: Individual | G120: Office Chair | H120: Furniture | I120: 2 | J120: 10780 | K120: 0.08 | L120: Debit Card | M120: Neha Kapoor | N120: Delivered | O120: 21560 | P120: 1724.8 | Q120: 19835.2 | R120: 2 | S120: =DATE(YEAR(B120),MONTH(B120),1) -> 45870
A121: ORD-10072 | B121: 45901 | C121: South | D121: Kochi | E121: Retail Store | F121: Small Business | G121: Webcam | H121: Accessories | I121: 1 | J121: 3750 | K121: 0.08 | L121: UPI | M121: Rohan Sharma | N121: Cancelled | O121: 0 | P121: 0 | Q121: 0 | S121: =DATE(YEAR(B121),MONTH(B121),1) -> 45901
A122: ORD-10273 | B122: 45901 | C122: West | D122: Surat | E122: Retail Store | F122: Individual | G122: Mouse | H122: Accessories | I122: 1 | J122: 910 | K122: 0.15 | L122: Debit Card | M122: Ananya Rao | N122: Delivered | O122: 910 | P122: 136.5 | Q122: 773.5 | R122: 3 | S122: =DATE(YEAR(B122),MONTH(B122),1) -> 45901
A123: ORD-10060 | B123: 45901 | C123: West | D123: Surat | E123: Corporate | F123: Individual | G123: Smartphone | H123: Electronics | I123: 4 | J123: 27810 | K123: 0.03 | L123: Credit Card | M123: Karan Patel | N123: Delivered | O123: 111240 | P123: 3337.2 | Q123: 107902.8 | R123: 5 | S123: =DATE(YEAR(B123),MONTH(B123),1) -> 45901
A124: ORD-10369 | B124: 45903 | C124: South | D124: Bengaluru | E124: Online | F124: Individual | G124: External SSD | H124: Storage | I124: 1 | J124: 6750 | K124: 0 | L124: Net Banking | M124: Rohan Sharma | N124: Delivered | O124: 6750 | P124: 0 | Q124: 6750 | R124: 6 | S124: =DATE(YEAR(B124),MONTH(B124),1) -> 45901
A125: ORD-10452 | B125: 45903 | C125: West | D125: Mumbai | E125: Online | F125: Individual | G125: Backpack | H125: Accessories | I125: 1 | J125: 2450 | K125: 0 | L125: UPI | M125: Ananya Rao | N125: Delivered | O125: 2450 | P125: 0 | Q125: 2450 | R125: 2 | S125: =DATE(YEAR(B125),MONTH(B125),1) -> 45901
A126: ORD-10363 | B126: 45904 | C126: South | D126: Hyderabad | E126: Online | F126: Individual | G126: Monitor | H126: Electronics | I126: 5 | J126: 15940 | K126: 0.1 | L126: Net Banking | M126: Rohan Sharma | N126: Delivered | O126: 79700 | P126: 7970 | Q126: 71730 | R126: 2 | S126: =DATE(YEAR(B126),MONTH(B126),1) -> 45901
A127: ORD-10033 | B127: 45904 | C127: West | D127: Pune | E127: Online | F127: Individual | G127: External SSD | H127: Storage | I127: 5 | J127: 7250 | K127: 0.08 | L127: Credit Card | M127: Rohan Sharma | N127: Delivered | O127: 36250 | P127: 2900 | Q127: 33350 | R127: 2 | S127: =DATE(YEAR(B127),MONTH(B127),1) -> 45901
A128: ORD-10249 | B128: 45904 | C128: South | D128: Hyderabad | E128: Retail Store | F128: Small Business | G128: Tablet | H128: Electronics | I128: 2 | J128: 22660 | K128: 0.05 | L128: Credit Card | M128: Sneha Iyer | N128: Delivered | O128: 45320 | P128: 2266 | Q128: 43054 | R128: 4 | S128: =DATE(YEAR(B128),MONTH(B128),1) -> 45901
...

Sheet Analysis
A1: Total Net Sales | B1: =SUM(Table2[Net Sales INR]) -> 20805536
A3: Category | B3: Electronics | D3: Region | E3: Category | F3: Sum of Net Sales INR | H3: Total orders | I3: =COUNTA(Table2[Order ID]) -> 650
A4: Net Sales By Region | D4: East | E4: Accessories | F4: 120644.7 | H4: Average order value | I4: =B1/I3 -> 32008.516
A5: Region | B5: Sum of Net Sales INR | E5: Electronics | F5: 1587261.8
A6: East | B6: 1587261.8 | E6: Furniture | F6: 269369.6 | H6: Sales Channel | I6: Sum of Net Sales INR
A7: North | B7: 3140337.1 | E7: Office Equipment | F7: 117757.8 | H7: Corporate | I7: 3396095.8
A8: South | B8: 6643505.4 | E8: Storage | F8: 160603.3 | H8: Online | I8: 9729336.7
A9: West | B9: 4820276.5 | D9: East Total | F9: 2255637.2 | H9: Retail Store | I9: 7680103
A10: Grand Total | B10: 16191381 | D10: North | E10: Accessories | F10: 157598.8 | H10: Grand Total | I10: 20805536
E11: Electronics | F11: 3140337.1
A12: Net sales by product | E12: Furniture | F12: 533239.6
A13: Category | B13: Sum of Net Sales INR | E13: Office Equipment | F13: 70908.6
A14: Accessories | B14: 777184.8 | E14: Storage | F14: 193450.6
A15: Electronics | B15: 16191381 | D15: North Total | F15: 4095534.7
A16: Furniture | B16: 2412867.4 | D16: South | E16: Accessories | F16: 262422.4
A17: Office Equipment | B17: 610226 | E17: Electronics | F17: 6643505.4
A18: Storage | B18: 813876.5 | E18: Furniture | F18: 1025116.2
A19: Grand Total | B19: 20805536 | E19: Office Equipment | F19: 246737.6
E20: Storage | F20: 277185.9
A21: Order Status | D21: South Total | F21: 8454967.5
A22: Order Status | B22: Count of Order ID | D22: West | E22: Accessories | F22: 236518.9
A23: Cancelled | B23: 21 | E23: Electronics | F23: 4820276.5
A24: Delivered | B24: 616 | E24: Furniture | F24: 585142
A25: Returned | B25: 13 | E25: Office Equipment | F25: 174822
A26: Grand Total | B26: 650 | E26: Storage | F26: 182636.7
D27: West Total | F27: 5999396.1
A28: Cancellation rate | B28: =B23/B26 -> 0.032307692 | D28: Grand Total | F28: 20805535
A29: Return rate | B29: =B25/B26 -> 0.02
A32: Sales Month | B32: Sum of Net Sales INR
A33: 45839 | B33: 2445250.7
A34: 45870 | B34: 1299864.5
A35: 45901 | B35: 1267369.1
A36: 45931 | B36: 1603880.7
A37: 45962 | B37: 1501010.1
A38: 45992 | B38: 1699782.5
A39: 46023 | B39: 1958918.2
A40: 46054 | B40: 1120508.9
A41: 46082 | B41: 2872539.2
A42: 46113 | B42: 1374952.3
A43: 46143 | B43: 2113859.5
...

Sheet Dashboard
A1: KEY PERFORMANCE AREAS
A3: TOTAL NET SALES | B3: TOTAL ORDERS | C3: AVERAGE ORDER VALUE | D3: CANCELLATION RATE | E3: RETURN RATE
A4: =Analysis!B1 -> 20805536 | B4: =Analysis!B26 -> 650 | C4: =Analysis!I4 -> 32008.516 | D4: =Analysis!B28 -> 0.032307692 | E4: =Analysis!B29 -> 0.02
A6: KEY INSIGHTS
A7: 1. Electronics dominates sales
A8: Electronics generated approximately 77.8% of total net sales, making it by far the largest revenue-driving category.
A9: 2. South is the strongest region
A10: South generated approximately 40.6% of total net sales, the highest among the four regions.
A11: 3. Online is the leading sales channel
A12: Online generated approximately 46.8% of total net sales, ahead of Retail Store and Corporate.
A13: 4. March 2026 was the strongest month
A14: March 2026 generated approximately ₹2.87M, the highest monthly net sales in the dataset.

Sheet Documentation
A1: Retail Sales Performance Analysis Project
A2: Excel | Data Cleaning | PivotTables | Data Visualization
A4: PROJECT OBJECTIVE
A5: Analyze retail sales data to understand revenue performance, customer orders, product categories, sales channels, regional performance, and order outcomes using Excel.
A7: BUSINESS QUESTIONS
A8: How much net sales did the business generate?
A9: Which regions generate the most revenue?
A10: Which product categories drive sales?
A11: Which sales channel performs best?
A12: How has sales performance changed over time?
A13: What proportion of orders are cancelled or returned?
A15: DATASET
... A75: Business insights
